<?xml version="1.0" ?>
<robot name="two_axis_manipulator" xmlns:xacro="http://www.ros.org/wiki/xacro">

<xacro:include filename="$(find two_axis_manipulator_description)/urdf/materials.xacro" />
<xacro:include filename="$(find two_axis_manipulator_description)/urdf/two_axis_manipulator.trans" />
<xacro:include filename="$(find two_axis_manipulator_description)/urdf/two_axis_manipulator.gazebo" />
<link name="link1">
  <inertial>
    <origin xyz="-0.028489844749223864 -0.0042819271393418 0.003029979921764912" rpy="0 0 0"/>
    <mass value="0.6681040624387208"/>
    <inertia ixx="0.00376" iyy="0.005272" izz="0.008817" ixy="-0.000229" iyz="0.000154" ixz="9.6e-05"/>
  </inertial>
  <visual>
    <origin xyz="0 0 0" rpy="0 0 0"/>
    <geometry>
      <mesh filename="file://$(find two_axis_manipulator_description)/meshes/link1.stl" scale="0.001 0.001 0.001"/>
    </geometry>
    <material name="silver"/>
  </visual>
  <collision>
    <origin xyz="0 0 0" rpy="0 0 0"/>
    <geometry>
      <mesh filename="file://$(find two_axis_manipulator_description)/meshes/link1.stl" scale="0.001 0.001 0.001"/>
    </geometry>
  </collision>
</link>

<link name="link2">
  <inertial>
    <origin xyz="0.025757744162237486 -9.095444257478658e-08 -0.025149867597073286" rpy="0 0 0"/>
    <mass value="0.10098055947342642"/>
    <inertia ixx="2.5e-05" iyy="9.7e-05" izz="8e-05" ixy="0.0" iyz="-0.0" ixz="-1e-06"/>
  </inertial>
  <visual>
    <origin xyz="0.074 0.109897 -0.0708" rpy="0 0 0"/>
    <geometry>
      <mesh filename="file://$(find two_axis_manipulator_description)/meshes/link2.stl" scale="0.001 0.001 0.001"/>
    </geometry>
    <material name="silver"/>
  </visual>
  <collision>
    <origin xyz="0.074 0.109897 -0.0708" rpy="0 0 0"/>
    <geometry>
      <mesh filename="file://$(find two_axis_manipulator_description)/meshes/link2.stl" scale="0.001 0.001 0.001"/>
    </geometry>
  </collision>
</link>

<link name="link3">
  <inertial>
    <origin xyz="0.026934734885223178 5.378547984769e-08 -0.025394549004305524" rpy="0 0 0"/>
    <mass value="0.10799512775205851"/>
    <inertia ixx="2.4e-05" iyy="9.6e-05" izz="8.2e-05" ixy="-0.0" iyz="0.0" ixz="0.0"/>
  </inertial>
  <visual>
    <origin xyz="-0.01612 0.109897 -0.0708" rpy="0 0 0"/>
    <geometry>
      <mesh filename="file://$(find two_axis_manipulator_description)/meshes/link3.stl" scale="0.001 0.001 0.001"/>
    </geometry>
    <material name="silver"/>
  </visual>
  <collision>
    <origin xyz="-0.01612 0.109897 -0.0708" rpy="0 0 0"/>
    <geometry>
      <mesh filename="file://$(find two_axis_manipulator_description)/meshes/link3.stl" scale="0.001 0.001 0.001"/>
    </geometry>
  </collision>
</link>

<link name="link4">
  <inertial>
    <origin xyz="6.675215935558754e-15 -9.095444264417551e-08 0.02134923455920878" rpy="0 0 0"/>
    <mass value="0.0038258048079866666"/>
    <inertia ixx="1e-06" iyy="1e-06" izz="0.0" ixy="0.0" iyz="-0.0" ixz="0.0"/>
  </inertial>
  <visual>
    <origin xyz="-0.09594 0.109897 -0.0236" rpy="0 0 0"/>
    <geometry>
      <mesh filename="file://$(find two_axis_manipulator_description)/meshes/link4.stl" scale="0.001 0.001 0.001"/>
    </geometry>
    <material name="silver"/>
  </visual>
  <collision>
    <origin xyz="-0.09594 0.109897 -0.0236" rpy="0 0 0"/>
    <geometry>
      <mesh filename="file://$(find two_axis_manipulator_description)/meshes/link4.stl" scale="0.001 0.001 0.001"/>
    </geometry>
  </collision>
</link>

<joint name="joint1" type="revolute">
  <origin xyz="-0.074 -0.109897 0.0708" rpy="0 0 0"/>
  <parent link="link1"/>
  <child link="link2"/>
  <axis xyz="0.0 0.0 -1.0"/>
  <limit upper="2.094395" lower="-2.094395" effort="100" velocity="4.8"/>
</joint>

<joint name="joint2" type="revolute">
  <origin xyz="0.09012 0.0 0.0" rpy="0 0 0"/>
  <parent link="link2"/>
  <child link="link3"/>
  <axis xyz="0.0 -0.0 -1.0"/>
  <limit upper="2.094395" lower="-2.094395" effort="100" velocity="4.8"/>
</joint>

<joint name="joint3" type="continuous">
  <origin xyz="0.07982 0.0 -0.0472" rpy="0 0 0"/>
  <parent link="link3"/>
  <child link="link4"/>
  <axis xyz="-0.0 0.0 1.0"/>
</joint>

</robot>
